2020-07-08 20:56:59,708 - [handlelog.py-->line:39] - INFO:调试一下下
2020-07-08 20:58:04,304 - [handlelog.py-->line:39] - INFO:调试一下下
2020-07-08 20:58:04,713 - [test_login.py-->line:54] - INFO:用例登录成功执行通过
2020-07-08 20:58:04,818 - [test_login.py-->line:54] - INFO:用例账号不正确执行通过
2020-07-08 21:03:41,523 - [handlelog.py-->line:39] - INFO:调试一下下
2020-07-08 21:03:42,119 - [test_login.py-->line:54] - INFO:用例登录成功执行通过
2020-07-08 21:03:42,305 - [test_login.py-->line:54] - INFO:用例账号不正确执行通过
2020-07-08 21:03:45,422 - [handlelog.py-->line:39] - INFO:调试一下下
2020-07-08 21:03:45,842 - [test_login.py-->line:54] - INFO:用例登录成功执行通过
2020-07-08 21:03:45,966 - [test_login.py-->line:54] - INFO:用例账号不正确执行通过
2020-07-08 21:56:30,331 - [handlelog.py-->line:39] - INFO:调试一下下
2020-07-08 21:56:31,020 - [test_login.py-->line:54] - INFO:用例登录成功执行通过
2020-07-08 21:56:31,134 - [test_login.py-->line:54] - INFO:用例账号不正确执行通过
2020-07-08 22:00:24,665 - [handlelog.py-->line:39] - INFO:调试一下下
2020-07-08 22:00:25,350 - [test_login.py-->line:54] - INFO:用例登录成功执行通过
2020-07-08 22:00:25,461 - [test_login.py-->line:54] - INFO:用例账号不正确执行通过
2020-07-09 22:05:11,838 - [handlelog.py-->line:39] - INFO:调试一下下
2020-07-09 22:05:12,340 - [test_login.py-->line:54] - INFO:用例登录成功执行通过
2020-07-09 22:05:12,458 - [test_login.py-->line:54] - INFO:用例账号不正确执行通过
2020-07-09 22:05:31,874 - [handlelog.py-->line:39] - INFO:调试一下下
2020-07-09 22:05:32,317 - [test_login.py-->line:54] - INFO:用例登录成功执行通过
2020-07-09 22:05:32,423 - [test_login.py-->line:54] - INFO:用例账号不正确执行通过
2020-07-09 22:06:07,116 - [handlelog.py-->line:39] - INFO:调试一下下
2020-07-09 22:06:07,549 - [test_login.py-->line:54] - INFO:用例登录成功执行通过
2020-07-09 22:06:07,655 - [test_login.py-->line:54] - INFO:用例账号不正确执行通过
2020-07-09 22:06:12,612 - [handlelog.py-->line:39] - INFO:调试一下下
2020-07-09 22:06:13,031 - [test_login.py-->line:54] - INFO:用例登录成功执行通过
2020-07-09 22:06:13,138 - [test_login.py-->line:54] - INFO:用例账号不正确执行通过
2020-07-09 22:09:21,257 - [handlelog.py-->line:39] - INFO:调试一下下
2020-07-09 22:09:21,667 - [test_login.py-->line:54] - INFO:用例登录成功执行通过
2020-07-09 22:09:21,773 - [test_login.py-->line:54] - INFO:用例账号不正确执行通过
2020-07-09 22:11:23,652 - [handlelog.py-->line:39] - INFO:调试一下下
2020-07-09 22:11:24,062 - [test_login.py-->line:54] - INFO:用例登录成功执行通过
2020-07-09 22:11:24,171 - [test_login.py-->line:54] - INFO:用例账号不正确执行通过
2020-07-09 22:17:20,843 - [handlelog.py-->line:39] - INFO:调试一下下
2020-07-09 22:17:21,262 - [test_login.py-->line:54] - INFO:用例登录成功执行通过
2020-07-09 22:17:21,369 - [test_login.py-->line:54] - INFO:用例账号不正确执行通过
2020-08-05 00:27:08,902 - [handlelog.py-->line:39] - INFO:调试一下下
2020-08-05 00:27:58,982 - [handlelog.py-->line:39] - INFO:调试一下下
2020-08-05 00:31:31,620 - [handlelog.py-->line:39] - INFO:调试一下下
2020-08-05 00:32:37,694 - [handlelog.py-->line:39] - INFO:调试一下下
2020-08-05 00:32:38,090 - [test_login.py-->line:54] - INFO:用例登录成功执行通过
2020-08-05 00:32:38,200 - [test_login.py-->line:54] - INFO:用例账号不正确执行通过
2020-08-05 00:35:00,325 - [handlelog.py-->line:39] - INFO:调试一下下
2020-08-05 00:35:00,727 - [test_login.py-->line:54] - INFO:用例登录成功执行通过
2020-08-05 00:35:00,829 - [test_login.py-->line:54] - INFO:用例账号不正确执行通过
2020-08-05 00:37:03,571 - [handlelog.py-->line:39] - INFO:调试一下下
2020-08-05 00:37:03,970 - [test_login.py-->line:54] - INFO:用例登录成功执行通过
2020-08-05 00:37:04,089 - [test_login.py-->line:54] - INFO:用例账号不正确执行通过
2020-08-05 00:38:49,277 - [handlelog.py-->line:39] - INFO:调试一下下
2020-08-05 00:38:49,713 - [test_login.py-->line:54] - INFO:用例登录成功执行通过
2020-08-05 00:38:49,836 - [test_login.py-->line:54] - INFO:用例账号不正确执行通过
2020-08-05 00:39:33,048 - [handlelog.py-->line:39] - INFO:调试一下下
2020-08-05 00:40:20,474 - [handlelog.py-->line:39] - INFO:调试一下下
2020-08-05 00:41:01,662 - [handlelog.py-->line:39] - INFO:调试一下下
2020-08-05 00:43:20,617 - [handlelog.py-->line:39] - INFO:调试一下下
2020-08-05 00:44:02,835 - [handlelog.py-->line:39] - INFO:调试一下下
2020-08-05 01:04:13,353 - [handlelog.py-->line:39] - INFO:调试一下下
2020-08-05 01:04:48,653 - [handlelog.py-->line:39] - INFO:调试一下下
2020-08-05 01:04:49,090 - [test_login.py-->line:54] - INFO:用例登录成功执行通过
2020-08-05 01:04:49,194 - [test_login.py-->line:54] - INFO:用例账号不正确执行通过
2020-08-10 22:42:14,489 - [handlelog.py-->line:39] - INFO:调试一下下
2020-08-10 22:42:15,331 - [test_login.py-->line:54] - INFO:用例登录成功执行通过
2020-08-10 22:42:15,526 - [test_login.py-->line:54] - INFO:用例账号不正确执行通过
2020-08-27 20:25:20,489 - [handlelog.py-->line:39] - INFO:调试一下下
2020-08-27 20:27:51,571 - [handlelog.py-->line:39] - INFO:调试一下下
2020-08-27 20:28:12,652 - [handlelog.py-->line:39] - INFO:调试一下下
2020-08-27 20:29:04,529 - [handlelog.py-->line:39] - INFO:调试一下下
2020-08-27 20:31:58,499 - [handlelog.py-->line:39] - INFO:调试一下下
2020-08-27 20:32:44,077 - [handlelog.py-->line:39] - INFO:调试一下下
2020-08-27 20:34:49,936 - [handlelog.py-->line:39] - INFO:调试一下下
2020-08-27 20:43:56,803 - [handlelog.py-->line:39] - INFO:调试一下下
2020-08-27 20:45:31,648 - [handlelog.py-->line:39] - INFO:调试一下下
2020-08-27 20:46:55,226 - [handlelog.py-->line:39] - INFO:调试一下下
2020-08-27 20:47:07,595 - [handlelog.py-->line:39] - INFO:调试一下下
2020-08-27 20:47:49,075 - [handlelog.py-->line:39] - INFO:调试一下下
2020-08-27 20:47:56,482 - [test_login.py-->line:54] - INFO:用例登录成功执行通过
2020-08-27 20:47:56,591 - [test_login.py-->line:54] - INFO:用例账号不正确执行通过
2020-08-27 20:50:40,351 - [handlelog.py-->line:39] - INFO:调试一下下
2020-08-27 20:51:14,700 - [handlelog.py-->line:39] - INFO:调试一下下
2020-08-27 20:56:14,283 - [handlelog.py-->line:39] - INFO:调试一下下
2020-08-27 21:02:58,969 - [handlelog.py-->line:39] - INFO:调试一下下
2020-08-27 21:06:24,500 - [handlelog.py-->line:39] - INFO:调试一下下
2020-08-27 21:09:28,402 - [handlelog.py-->line:39] - INFO:调试一下下
2020-08-27 21:10:01,028 - [handlelog.py-->line:39] - INFO:调试一下下
2020-08-27 21:10:06,474 - [handlelog.py-->line:39] - INFO:调试一下下
2020-08-27 21:10:09,814 - [handlelog.py-->line:39] - INFO:调试一下下
2020-08-27 21:11:35,536 - [handlelog.py-->line:39] - INFO:调试一下下
2020-08-27 21:11:42,235 - [handlelog.py-->line:39] - INFO:调试一下下
2020-08-27 21:11:45,788 - [handlelog.py-->line:39] - INFO:调试一下下
2020-08-27 21:11:54,966 - [handlelog.py-->line:39] - INFO:调试一下下
2020-08-27 21:12:03,037 - [handlelog.py-->line:39] - INFO:调试一下下
2020-08-27 21:12:16,618 - [handlelog.py-->line:39] - INFO:调试一下下
2020-08-27 21:14:27,668 - [handlelog.py-->line:39] - INFO:调试一下下
2020-08-27 21:15:01,858 - [handlelog.py-->line:39] - INFO:调试一下下
2020-08-27 21:16:37,103 - [handlelog.py-->line:39] - INFO:调试一下下
2020-08-27 21:17:13,407 - [handlelog.py-->line:39] - INFO:调试一下下
2020-08-27 21:17:26,086 - [handlelog.py-->line:39] - INFO:调试一下下
2020-08-27 21:18:26,295 - [handlelog.py-->line:39] - INFO:调试一下下
2020-08-27 21:18:31,735 - [handlelog.py-->line:39] - INFO:调试一下下
2020-08-27 21:19:06,141 - [handlelog.py-->line:39] - INFO:调试一下下
2020-08-27 21:20:39,500 - [handlelog.py-->line:39] - INFO:调试一下下
2020-08-27 21:39:34,776 - [handlelog.py-->line:39] - INFO:调试一下下
2020-08-27 21:41:18,515 - [handlelog.py-->line:39] - INFO:调试一下下
2020-08-27 21:48:24,698 - [handlelog.py-->line:39] - INFO:调试一下下
2020-08-27 21:48:38,457 - [handlelog.py-->line:39] - INFO:调试一下下
2020-08-27 21:48:38,886 - [test_login.py-->line:54] - INFO:用例登录成功执行通过
2020-08-27 21:48:38,998 - [test_login.py-->line:54] - INFO:用例账号不正确执行通过
2020-08-27 21:53:23,537 - [handlelog.py-->line:39] - INFO:调试一下下
2020-08-27 21:53:24,201 - [test_login.py-->line:54] - INFO:用例登录成功执行通过
2020-08-27 21:53:24,312 - [test_login.py-->line:54] - INFO:用例账号不正确执行通过
2020-08-27 21:53:24,598 - [test_my_push.py-->line:82] - ERROR:用例全部店铺执行不通过
2020-08-27 21:53:24,598 - [test_my_push.py-->line:84] - ERROR:1 != 2
Traceback (most recent call last):
  File "D:\PyCharm Community Edition 2020.1.1\kuangjia_new\testcases\test_my_push.py", line 76, in test001_my_push
    self.assertEqual(expected['code'], result['code'])
  File "C:\Users\22235\AppData\Local\Programs\Python\Python37\lib\unittest\case.py", line 852, in assertEqual
    assertion_func(first, second, msg=msg)
  File "C:\Users\22235\AppData\Local\Programs\Python\Python37\lib\unittest\case.py", line 845, in _baseAssertEqual
    raise self.failureException(msg)
AssertionError: 1 != 2
2020-08-27 21:53:24,710 - [test_my_push.py-->line:82] - ERROR:用例上架中执行不通过
2020-08-27 21:53:24,710 - [test_my_push.py-->line:84] - ERROR:1 != 2
Traceback (most recent call last):
  File "D:\PyCharm Community Edition 2020.1.1\kuangjia_new\testcases\test_my_push.py", line 76, in test001_my_push
    self.assertEqual(expected['code'], result['code'])
  File "C:\Users\22235\AppData\Local\Programs\Python\Python37\lib\unittest\case.py", line 852, in assertEqual
    assertion_func(first, second, msg=msg)
  File "C:\Users\22235\AppData\Local\Programs\Python\Python37\lib\unittest\case.py", line 845, in _baseAssertEqual
    raise self.failureException(msg)
AssertionError: 1 != 2
2020-08-27 21:53:24,808 - [test_my_push.py-->line:82] - ERROR:用例店铺分类为空执行不通过
2020-08-27 21:53:24,809 - [test_my_push.py-->line:84] - ERROR:0 != 2
Traceback (most recent call last):
  File "D:\PyCharm Community Edition 2020.1.1\kuangjia_new\testcases\test_my_push.py", line 76, in test001_my_push
    self.assertEqual(expected['code'], result['code'])
  File "C:\Users\22235\AppData\Local\Programs\Python\Python37\lib\unittest\case.py", line 852, in assertEqual
    assertion_func(first, second, msg=msg)
  File "C:\Users\22235\AppData\Local\Programs\Python\Python37\lib\unittest\case.py", line 845, in _baseAssertEqual
    raise self.failureException(msg)
AssertionError: 0 != 2
2020-08-27 21:54:46,831 - [handlelog.py-->line:39] - INFO:调试一下下
2020-08-27 21:54:47,539 - [test_login.py-->line:54] - INFO:用例登录成功执行通过
2020-08-27 21:54:47,662 - [test_login.py-->line:54] - INFO:用例账号不正确执行通过
2020-08-27 21:54:48,377 - [test_my_push.py-->line:90] - INFO:用例全部店铺执行通过
2020-08-27 21:54:48,541 - [test_my_push.py-->line:90] - INFO:用例上架中执行通过
2020-08-27 21:54:48,648 - [test_my_push.py-->line:90] - INFO:用例店铺分类为空执行通过
2020-08-27 22:06:55,525 - [handlelog.py-->line:39] - INFO:调试一下下
2020-08-27 22:06:55,948 - [test_my_push.py-->line:82] - ERROR:用例全部店铺执行不通过
2020-08-27 22:06:55,949 - [test_my_push.py-->line:84] - ERROR: :: 1 != 2
Traceback (most recent call last):
  File "D:\PyCharm Community Edition 2020.1.1\plugins\python-ce\helpers\pycharm\teamcity\diff_tools.py", line 32, in _patched_equals
    old(self, first, second, msg)
  File "C:\Users\22235\AppData\Local\Programs\Python\Python37\lib\unittest\case.py", line 852, in assertEqual
    assertion_func(first, second, msg=msg)
  File "C:\Users\22235\AppData\Local\Programs\Python\Python37\lib\unittest\case.py", line 845, in _baseAssertEqual
    raise self.failureException(msg)
AssertionError: 1 != 2

During handling of the above exception, another exception occurred:

Traceback (most recent call last):
  File "D:\PyCharm Community Edition 2020.1.1\kuangjia_new\testcases\test_my_push.py", line 76, in test001_my_push
    self.assertEqual(expected['code'], result['code'])
  File "D:\PyCharm Community Edition 2020.1.1\plugins\python-ce\helpers\pycharm\teamcity\diff_tools.py", line 38, in _patched_equals
    raise error
teamcity.diff_tools.EqualsAssertionError:  :: 1 != 2
2020-08-27 22:06:56,068 - [test_my_push.py-->line:82] - ERROR:用例上架中执行不通过
2020-08-27 22:06:56,068 - [test_my_push.py-->line:84] - ERROR: :: 1 != 2
Traceback (most recent call last):
  File "D:\PyCharm Community Edition 2020.1.1\plugins\python-ce\helpers\pycharm\teamcity\diff_tools.py", line 32, in _patched_equals
    old(self, first, second, msg)
  File "C:\Users\22235\AppData\Local\Programs\Python\Python37\lib\unittest\case.py", line 852, in assertEqual
    assertion_func(first, second, msg=msg)
  File "C:\Users\22235\AppData\Local\Programs\Python\Python37\lib\unittest\case.py", line 845, in _baseAssertEqual
    raise self.failureException(msg)
AssertionError: 1 != 2

During handling of the above exception, another exception occurred:

Traceback (most recent call last):
  File "D:\PyCharm Community Edition 2020.1.1\kuangjia_new\testcases\test_my_push.py", line 76, in test001_my_push
    self.assertEqual(expected['code'], result['code'])
  File "D:\PyCharm Community Edition 2020.1.1\plugins\python-ce\helpers\pycharm\teamcity\diff_tools.py", line 38, in _patched_equals
    raise error
teamcity.diff_tools.EqualsAssertionError:  :: 1 != 2
2020-08-27 22:06:56,182 - [test_my_push.py-->line:82] - ERROR:用例店铺分类为空执行不通过
2020-08-27 22:06:56,182 - [test_my_push.py-->line:84] - ERROR: :: 0 != 2
Traceback (most recent call last):
  File "D:\PyCharm Community Edition 2020.1.1\plugins\python-ce\helpers\pycharm\teamcity\diff_tools.py", line 32, in _patched_equals
    old(self, first, second, msg)
  File "C:\Users\22235\AppData\Local\Programs\Python\Python37\lib\unittest\case.py", line 852, in assertEqual
    assertion_func(first, second, msg=msg)
  File "C:\Users\22235\AppData\Local\Programs\Python\Python37\lib\unittest\case.py", line 845, in _baseAssertEqual
    raise self.failureException(msg)
AssertionError: 0 != 2

During handling of the above exception, another exception occurred:

Traceback (most recent call last):
  File "D:\PyCharm Community Edition 2020.1.1\kuangjia_new\testcases\test_my_push.py", line 76, in test001_my_push
    self.assertEqual(expected['code'], result['code'])
  File "D:\PyCharm Community Edition 2020.1.1\plugins\python-ce\helpers\pycharm\teamcity\diff_tools.py", line 38, in _patched_equals
    raise error
teamcity.diff_tools.EqualsAssertionError:  :: 0 != 2
2020-08-27 22:22:05,139 - [handlelog.py-->line:39] - INFO:调试一下下
2020-08-27 22:22:28,518 - [test_my_push.py-->line:82] - ERROR:用例上架中执行不通过
2020-08-27 22:22:28,518 - [test_my_push.py-->line:84] - ERROR: :: 1 != 2
Traceback (most recent call last):
  File "D:\PyCharm Community Edition 2020.1.1\plugins\python-ce\helpers\pycharm\teamcity\diff_tools.py", line 32, in _patched_equals
    old(self, first, second, msg)
  File "C:\Users\22235\AppData\Local\Programs\Python\Python37\lib\unittest\case.py", line 852, in assertEqual
    assertion_func(first, second, msg=msg)
  File "C:\Users\22235\AppData\Local\Programs\Python\Python37\lib\unittest\case.py", line 845, in _baseAssertEqual
    raise self.failureException(msg)
AssertionError: 1 != 2

During handling of the above exception, another exception occurred:

Traceback (most recent call last):
  File "D:\PyCharm Community Edition 2020.1.1\kuangjia_new\testcases\test_my_push.py", line 76, in test001_my_push
    self.assertEqual(expected['code'], result['code'])
  File "D:\PyCharm Community Edition 2020.1.1\plugins\python-ce\helpers\pycharm\teamcity\diff_tools.py", line 38, in _patched_equals
    raise error
teamcity.diff_tools.EqualsAssertionError:  :: 1 != 2
2020-08-27 22:22:28,632 - [test_my_push.py-->line:82] - ERROR:用例店铺分类为空执行不通过
2020-08-27 22:22:28,632 - [test_my_push.py-->line:84] - ERROR: :: 0 != 2
Traceback (most recent call last):
  File "D:\PyCharm Community Edition 2020.1.1\plugins\python-ce\helpers\pycharm\teamcity\diff_tools.py", line 32, in _patched_equals
    old(self, first, second, msg)
  File "C:\Users\22235\AppData\Local\Programs\Python\Python37\lib\unittest\case.py", line 852, in assertEqual
    assertion_func(first, second, msg=msg)
  File "C:\Users\22235\AppData\Local\Programs\Python\Python37\lib\unittest\case.py", line 845, in _baseAssertEqual
    raise self.failureException(msg)
AssertionError: 0 != 2

During handling of the above exception, another exception occurred:

Traceback (most recent call last):
  File "D:\PyCharm Community Edition 2020.1.1\kuangjia_new\testcases\test_my_push.py", line 76, in test001_my_push
    self.assertEqual(expected['code'], result['code'])
  File "D:\PyCharm Community Edition 2020.1.1\plugins\python-ce\helpers\pycharm\teamcity\diff_tools.py", line 38, in _patched_equals
    raise error
teamcity.diff_tools.EqualsAssertionError:  :: 0 != 2
2020-08-27 22:22:46,123 - [handlelog.py-->line:39] - INFO:调试一下下
2020-08-27 22:23:25,795 - [handlelog.py-->line:39] - INFO:调试一下下
2020-08-27 22:23:26,145 - [test_my_push.py-->line:82] - ERROR:用例全部店铺执行不通过
2020-08-27 22:23:26,145 - [test_my_push.py-->line:84] - ERROR: :: 1 != 2
Traceback (most recent call last):
  File "D:\PyCharm Community Edition 2020.1.1\plugins\python-ce\helpers\pycharm\teamcity\diff_tools.py", line 32, in _patched_equals
    old(self, first, second, msg)
  File "C:\Users\22235\AppData\Local\Programs\Python\Python37\lib\unittest\case.py", line 852, in assertEqual
    assertion_func(first, second, msg=msg)
  File "C:\Users\22235\AppData\Local\Programs\Python\Python37\lib\unittest\case.py", line 845, in _baseAssertEqual
    raise self.failureException(msg)
AssertionError: 1 != 2

During handling of the above exception, another exception occurred:

Traceback (most recent call last):
  File "D:\PyCharm Community Edition 2020.1.1\kuangjia_new\testcases\test_my_push.py", line 76, in test001_my_push
    self.assertEqual(expected['code'], result['code'])
  File "D:\PyCharm Community Edition 2020.1.1\plugins\python-ce\helpers\pycharm\teamcity\diff_tools.py", line 38, in _patched_equals
    raise error
teamcity.diff_tools.EqualsAssertionError:  :: 1 != 2
2020-08-27 22:23:26,251 - [test_my_push.py-->line:82] - ERROR:用例上架中执行不通过
2020-08-27 22:23:26,251 - [test_my_push.py-->line:84] - ERROR: :: 1 != 2
Traceback (most recent call last):
  File "D:\PyCharm Community Edition 2020.1.1\plugins\python-ce\helpers\pycharm\teamcity\diff_tools.py", line 32, in _patched_equals
    old(self, first, second, msg)
  File "C:\Users\22235\AppData\Local\Programs\Python\Python37\lib\unittest\case.py", line 852, in assertEqual
    assertion_func(first, second, msg=msg)
  File "C:\Users\22235\AppData\Local\Programs\Python\Python37\lib\unittest\case.py", line 845, in _baseAssertEqual
    raise self.failureException(msg)
AssertionError: 1 != 2

During handling of the above exception, another exception occurred:

Traceback (most recent call last):
  File "D:\PyCharm Community Edition 2020.1.1\kuangjia_new\testcases\test_my_push.py", line 76, in test001_my_push
    self.assertEqual(expected['code'], result['code'])
  File "D:\PyCharm Community Edition 2020.1.1\plugins\python-ce\helpers\pycharm\teamcity\diff_tools.py", line 38, in _patched_equals
    raise error
teamcity.diff_tools.EqualsAssertionError:  :: 1 != 2
2020-08-27 22:23:26,373 - [test_my_push.py-->line:82] - ERROR:用例店铺分类为空执行不通过
2020-08-27 22:23:26,374 - [test_my_push.py-->line:84] - ERROR: :: 0 != 2
Traceback (most recent call last):
  File "D:\PyCharm Community Edition 2020.1.1\plugins\python-ce\helpers\pycharm\teamcity\diff_tools.py", line 32, in _patched_equals
    old(self, first, second, msg)
  File "C:\Users\22235\AppData\Local\Programs\Python\Python37\lib\unittest\case.py", line 852, in assertEqual
    assertion_func(first, second, msg=msg)
  File "C:\Users\22235\AppData\Local\Programs\Python\Python37\lib\unittest\case.py", line 845, in _baseAssertEqual
    raise self.failureException(msg)
AssertionError: 0 != 2

During handling of the above exception, another exception occurred:

Traceback (most recent call last):
  File "D:\PyCharm Community Edition 2020.1.1\kuangjia_new\testcases\test_my_push.py", line 76, in test001_my_push
    self.assertEqual(expected['code'], result['code'])
  File "D:\PyCharm Community Edition 2020.1.1\plugins\python-ce\helpers\pycharm\teamcity\diff_tools.py", line 38, in _patched_equals
    raise error
teamcity.diff_tools.EqualsAssertionError:  :: 0 != 2
2020-08-27 22:24:53,988 - [handlelog.py-->line:39] - INFO:调试一下下
2020-08-27 22:24:54,663 - [test_my_push.py-->line:90] - INFO:用例全部店铺执行通过
2020-08-27 22:24:54,854 - [test_my_push.py-->line:90] - INFO:用例上架中执行通过
2020-08-27 22:24:54,969 - [test_my_push.py-->line:90] - INFO:用例店铺分类为空执行通过
2020-08-27 22:26:54,164 - [handlelog.py-->line:39] - INFO:调试一下下
2020-08-27 22:26:54,548 - [test_my_push.py-->line:82] - ERROR:用例全部店铺执行不通过
2020-08-27 22:26:54,548 - [test_my_push.py-->line:84] - ERROR: :: 1 != 2
Traceback (most recent call last):
  File "D:\PyCharm Community Edition 2020.1.1\plugins\python-ce\helpers\pycharm\teamcity\diff_tools.py", line 32, in _patched_equals
    old(self, first, second, msg)
  File "C:\Users\22235\AppData\Local\Programs\Python\Python37\lib\unittest\case.py", line 852, in assertEqual
    assertion_func(first, second, msg=msg)
  File "C:\Users\22235\AppData\Local\Programs\Python\Python37\lib\unittest\case.py", line 845, in _baseAssertEqual
    raise self.failureException(msg)
AssertionError: 1 != 2

During handling of the above exception, another exception occurred:

Traceback (most recent call last):
  File "D:\PyCharm Community Edition 2020.1.1\kuangjia_new\testcases\test_my_push.py", line 76, in test001_my_push
    self.assertEqual(expected['code'], result['code'])
  File "D:\PyCharm Community Edition 2020.1.1\plugins\python-ce\helpers\pycharm\teamcity\diff_tools.py", line 38, in _patched_equals
    raise error
teamcity.diff_tools.EqualsAssertionError:  :: 1 != 2
2020-08-27 22:26:54,670 - [test_my_push.py-->line:82] - ERROR:用例上架中执行不通过
2020-08-27 22:26:54,670 - [test_my_push.py-->line:84] - ERROR: :: 1 != 2
Traceback (most recent call last):
  File "D:\PyCharm Community Edition 2020.1.1\plugins\python-ce\helpers\pycharm\teamcity\diff_tools.py", line 32, in _patched_equals
    old(self, first, second, msg)
  File "C:\Users\22235\AppData\Local\Programs\Python\Python37\lib\unittest\case.py", line 852, in assertEqual
    assertion_func(first, second, msg=msg)
  File "C:\Users\22235\AppData\Local\Programs\Python\Python37\lib\unittest\case.py", line 845, in _baseAssertEqual
    raise self.failureException(msg)
AssertionError: 1 != 2

During handling of the above exception, another exception occurred:

Traceback (most recent call last):
  File "D:\PyCharm Community Edition 2020.1.1\kuangjia_new\testcases\test_my_push.py", line 76, in test001_my_push
    self.assertEqual(expected['code'], result['code'])
  File "D:\PyCharm Community Edition 2020.1.1\plugins\python-ce\helpers\pycharm\teamcity\diff_tools.py", line 38, in _patched_equals
    raise error
teamcity.diff_tools.EqualsAssertionError:  :: 1 != 2
2020-08-27 22:26:54,774 - [test_my_push.py-->line:82] - ERROR:用例店铺分类为空执行不通过
2020-08-27 22:26:54,775 - [test_my_push.py-->line:84] - ERROR: :: 0 != 2
Traceback (most recent call last):
  File "D:\PyCharm Community Edition 2020.1.1\plugins\python-ce\helpers\pycharm\teamcity\diff_tools.py", line 32, in _patched_equals
    old(self, first, second, msg)
  File "C:\Users\22235\AppData\Local\Programs\Python\Python37\lib\unittest\case.py", line 852, in assertEqual
    assertion_func(first, second, msg=msg)
  File "C:\Users\22235\AppData\Local\Programs\Python\Python37\lib\unittest\case.py", line 845, in _baseAssertEqual
    raise self.failureException(msg)
AssertionError: 0 != 2

During handling of the above exception, another exception occurred:

Traceback (most recent call last):
  File "D:\PyCharm Community Edition 2020.1.1\kuangjia_new\testcases\test_my_push.py", line 76, in test001_my_push
    self.assertEqual(expected['code'], result['code'])
  File "D:\PyCharm Community Edition 2020.1.1\plugins\python-ce\helpers\pycharm\teamcity\diff_tools.py", line 38, in _patched_equals
    raise error
teamcity.diff_tools.EqualsAssertionError:  :: 0 != 2
2020-08-27 22:38:12,031 - [handlelog.py-->line:39] - INFO:调试一下下
2020-08-27 22:38:21,684 - [handlelog.py-->line:39] - INFO:调试一下下
2020-08-27 22:41:43,851 - [handlelog.py-->line:39] - INFO:调试一下下
2020-08-27 22:41:53,379 - [test_my_push.py-->line:82] - ERROR:用例全部店铺执行不通过
2020-08-27 22:41:53,380 - [test_my_push.py-->line:84] - ERROR: :: 1 != 2
Traceback (most recent call last):
  File "D:\PyCharm Community Edition 2020.1.1\plugins\python-ce\helpers\pycharm\teamcity\diff_tools.py", line 32, in _patched_equals
    old(self, first, second, msg)
  File "C:\Users\22235\AppData\Local\Programs\Python\Python37\lib\unittest\case.py", line 852, in assertEqual
    assertion_func(first, second, msg=msg)
  File "C:\Users\22235\AppData\Local\Programs\Python\Python37\lib\unittest\case.py", line 845, in _baseAssertEqual
    raise self.failureException(msg)
AssertionError: 1 != 2

During handling of the above exception, another exception occurred:

Traceback (most recent call last):
  File "D:\PyCharm Community Edition 2020.1.1\kuangjia_new\testcases\test_my_push.py", line 76, in test001_my_push
    self.assertEqual(expected['code'], result['code'])
  File "D:\PyCharm Community Edition 2020.1.1\plugins\python-ce\helpers\pycharm\teamcity\diff_tools.py", line 38, in _patched_equals
    raise error
teamcity.diff_tools.EqualsAssertionError:  :: 1 != 2
2020-08-27 22:41:53,485 - [test_my_push.py-->line:82] - ERROR:用例上架中执行不通过
2020-08-27 22:41:53,486 - [test_my_push.py-->line:84] - ERROR: :: 1 != 2
Traceback (most recent call last):
  File "D:\PyCharm Community Edition 2020.1.1\plugins\python-ce\helpers\pycharm\teamcity\diff_tools.py", line 32, in _patched_equals
    old(self, first, second, msg)
  File "C:\Users\22235\AppData\Local\Programs\Python\Python37\lib\unittest\case.py", line 852, in assertEqual
    assertion_func(first, second, msg=msg)
  File "C:\Users\22235\AppData\Local\Programs\Python\Python37\lib\unittest\case.py", line 845, in _baseAssertEqual
    raise self.failureException(msg)
AssertionError: 1 != 2

During handling of the above exception, another exception occurred:

Traceback (most recent call last):
  File "D:\PyCharm Community Edition 2020.1.1\kuangjia_new\testcases\test_my_push.py", line 76, in test001_my_push
    self.assertEqual(expected['code'], result['code'])
  File "D:\PyCharm Community Edition 2020.1.1\plugins\python-ce\helpers\pycharm\teamcity\diff_tools.py", line 38, in _patched_equals
    raise error
teamcity.diff_tools.EqualsAssertionError:  :: 1 != 2
2020-08-27 22:41:53,585 - [test_my_push.py-->line:82] - ERROR:用例店铺分类为空执行不通过
2020-08-27 22:41:53,585 - [test_my_push.py-->line:84] - ERROR: :: 0 != 2
Traceback (most recent call last):
  File "D:\PyCharm Community Edition 2020.1.1\plugins\python-ce\helpers\pycharm\teamcity\diff_tools.py", line 32, in _patched_equals
    old(self, first, second, msg)
  File "C:\Users\22235\AppData\Local\Programs\Python\Python37\lib\unittest\case.py", line 852, in assertEqual
    assertion_func(first, second, msg=msg)
  File "C:\Users\22235\AppData\Local\Programs\Python\Python37\lib\unittest\case.py", line 845, in _baseAssertEqual
    raise self.failureException(msg)
AssertionError: 0 != 2

During handling of the above exception, another exception occurred:

Traceback (most recent call last):
  File "D:\PyCharm Community Edition 2020.1.1\kuangjia_new\testcases\test_my_push.py", line 76, in test001_my_push
    self.assertEqual(expected['code'], result['code'])
  File "D:\PyCharm Community Edition 2020.1.1\plugins\python-ce\helpers\pycharm\teamcity\diff_tools.py", line 38, in _patched_equals
    raise error
teamcity.diff_tools.EqualsAssertionError:  :: 0 != 2
2020-08-27 22:45:15,374 - [handlelog.py-->line:39] - INFO:调试一下下
2020-08-27 22:45:16,707 - [test_my_push.py-->line:82] - ERROR:用例全部店铺执行不通过
2020-08-27 22:45:16,707 - [test_my_push.py-->line:84] - ERROR:1 != 2
Traceback (most recent call last):
  File "D:/PyCharm Community Edition 2020.1.1/kuangjia_new/testcases/test_my_push.py", line 76, in test001_my_push
    self.assertEqual(expected['code'], result['code'])
  File "C:\Users\22235\AppData\Local\Programs\Python\Python37\lib\unittest\case.py", line 852, in assertEqual
    assertion_func(first, second, msg=msg)
  File "C:\Users\22235\AppData\Local\Programs\Python\Python37\lib\unittest\case.py", line 845, in _baseAssertEqual
    raise self.failureException(msg)
AssertionError: 1 != 2
2020-08-27 22:45:16,810 - [test_my_push.py-->line:82] - ERROR:用例上架中执行不通过
2020-08-27 22:45:16,810 - [test_my_push.py-->line:84] - ERROR:1 != 2
Traceback (most recent call last):
  File "D:/PyCharm Community Edition 2020.1.1/kuangjia_new/testcases/test_my_push.py", line 76, in test001_my_push
    self.assertEqual(expected['code'], result['code'])
  File "C:\Users\22235\AppData\Local\Programs\Python\Python37\lib\unittest\case.py", line 852, in assertEqual
    assertion_func(first, second, msg=msg)
  File "C:\Users\22235\AppData\Local\Programs\Python\Python37\lib\unittest\case.py", line 845, in _baseAssertEqual
    raise self.failureException(msg)
AssertionError: 1 != 2
2020-08-27 22:45:16,913 - [test_my_push.py-->line:82] - ERROR:用例店铺分类为空执行不通过
2020-08-27 22:45:16,913 - [test_my_push.py-->line:84] - ERROR:0 != 2
Traceback (most recent call last):
  File "D:/PyCharm Community Edition 2020.1.1/kuangjia_new/testcases/test_my_push.py", line 76, in test001_my_push
    self.assertEqual(expected['code'], result['code'])
  File "C:\Users\22235\AppData\Local\Programs\Python\Python37\lib\unittest\case.py", line 852, in assertEqual
    assertion_func(first, second, msg=msg)
  File "C:\Users\22235\AppData\Local\Programs\Python\Python37\lib\unittest\case.py", line 845, in _baseAssertEqual
    raise self.failureException(msg)
AssertionError: 0 != 2
2020-08-27 22:45:39,405 - [handlelog.py-->line:39] - INFO:调试一下下
2020-08-27 22:45:55,741 - [test_my_push.py-->line:82] - ERROR:用例全部店铺执行不通过
2020-08-27 22:45:55,741 - [test_my_push.py-->line:84] - ERROR:1 != 2
Traceback (most recent call last):
  File "D:/PyCharm Community Edition 2020.1.1/kuangjia_new/testcases/test_my_push.py", line 76, in test001_my_push
    self.assertEqual(expected['code'], result['code'])
  File "C:\Users\22235\AppData\Local\Programs\Python\Python37\lib\unittest\case.py", line 852, in assertEqual
    assertion_func(first, second, msg=msg)
  File "C:\Users\22235\AppData\Local\Programs\Python\Python37\lib\unittest\case.py", line 845, in _baseAssertEqual
    raise self.failureException(msg)
AssertionError: 1 != 2
2020-08-27 22:45:55,843 - [test_my_push.py-->line:82] - ERROR:用例上架中执行不通过
2020-08-27 22:45:55,844 - [test_my_push.py-->line:84] - ERROR:1 != 2
Traceback (most recent call last):
  File "D:/PyCharm Community Edition 2020.1.1/kuangjia_new/testcases/test_my_push.py", line 76, in test001_my_push
    self.assertEqual(expected['code'], result['code'])
  File "C:\Users\22235\AppData\Local\Programs\Python\Python37\lib\unittest\case.py", line 852, in assertEqual
    assertion_func(first, second, msg=msg)
  File "C:\Users\22235\AppData\Local\Programs\Python\Python37\lib\unittest\case.py", line 845, in _baseAssertEqual
    raise self.failureException(msg)
AssertionError: 1 != 2
2020-08-27 22:45:55,948 - [test_my_push.py-->line:82] - ERROR:用例店铺分类为空执行不通过
2020-08-27 22:45:55,948 - [test_my_push.py-->line:84] - ERROR:0 != 2
Traceback (most recent call last):
  File "D:/PyCharm Community Edition 2020.1.1/kuangjia_new/testcases/test_my_push.py", line 76, in test001_my_push
    self.assertEqual(expected['code'], result['code'])
  File "C:\Users\22235\AppData\Local\Programs\Python\Python37\lib\unittest\case.py", line 852, in assertEqual
    assertion_func(first, second, msg=msg)
  File "C:\Users\22235\AppData\Local\Programs\Python\Python37\lib\unittest\case.py", line 845, in _baseAssertEqual
    raise self.failureException(msg)
AssertionError: 0 != 2
2020-08-27 22:46:20,205 - [handlelog.py-->line:39] - INFO:调试一下下
2020-08-27 22:46:20,537 - [test_my_push.py-->line:82] - ERROR:用例全部店铺执行不通过
2020-08-27 22:46:20,537 - [test_my_push.py-->line:84] - ERROR:1 != 2
Traceback (most recent call last):
  File "D:/PyCharm Community Edition 2020.1.1/kuangjia_new/testcases/test_my_push.py", line 76, in test001_my_push
    self.assertEqual(expected['code'], result['code'])
  File "C:\Users\22235\AppData\Local\Programs\Python\Python37\lib\unittest\case.py", line 852, in assertEqual
    assertion_func(first, second, msg=msg)
  File "C:\Users\22235\AppData\Local\Programs\Python\Python37\lib\unittest\case.py", line 845, in _baseAssertEqual
    raise self.failureException(msg)
AssertionError: 1 != 2
2020-08-27 22:46:20,638 - [test_my_push.py-->line:82] - ERROR:用例上架中执行不通过
2020-08-27 22:46:20,638 - [test_my_push.py-->line:84] - ERROR:1 != 2
Traceback (most recent call last):
  File "D:/PyCharm Community Edition 2020.1.1/kuangjia_new/testcases/test_my_push.py", line 76, in test001_my_push
    self.assertEqual(expected['code'], result['code'])
  File "C:\Users\22235\AppData\Local\Programs\Python\Python37\lib\unittest\case.py", line 852, in assertEqual
    assertion_func(first, second, msg=msg)
  File "C:\Users\22235\AppData\Local\Programs\Python\Python37\lib\unittest\case.py", line 845, in _baseAssertEqual
    raise self.failureException(msg)
AssertionError: 1 != 2
2020-08-27 22:46:20,739 - [test_my_push.py-->line:82] - ERROR:用例店铺分类为空执行不通过
2020-08-27 22:46:20,739 - [test_my_push.py-->line:84] - ERROR:0 != 2
Traceback (most recent call last):
  File "D:/PyCharm Community Edition 2020.1.1/kuangjia_new/testcases/test_my_push.py", line 76, in test001_my_push
    self.assertEqual(expected['code'], result['code'])
  File "C:\Users\22235\AppData\Local\Programs\Python\Python37\lib\unittest\case.py", line 852, in assertEqual
    assertion_func(first, second, msg=msg)
  File "C:\Users\22235\AppData\Local\Programs\Python\Python37\lib\unittest\case.py", line 845, in _baseAssertEqual
    raise self.failureException(msg)
AssertionError: 0 != 2
2020-08-27 22:50:02,235 - [handlelog.py-->line:39] - INFO:调试一下下
2020-08-27 22:50:02,569 - [test_my_push.py-->line:82] - ERROR:用例全部店铺执行不通过
2020-08-27 22:50:02,569 - [test_my_push.py-->line:84] - ERROR: :: 1 != 2
Traceback (most recent call last):
  File "D:\PyCharm Community Edition 2020.1.1\plugins\python-ce\helpers\pycharm\teamcity\diff_tools.py", line 32, in _patched_equals
    old(self, first, second, msg)
  File "C:\Users\22235\AppData\Local\Programs\Python\Python37\lib\unittest\case.py", line 852, in assertEqual
    assertion_func(first, second, msg=msg)
  File "C:\Users\22235\AppData\Local\Programs\Python\Python37\lib\unittest\case.py", line 845, in _baseAssertEqual
    raise self.failureException(msg)
AssertionError: 1 != 2

During handling of the above exception, another exception occurred:

Traceback (most recent call last):
  File "D:\PyCharm Community Edition 2020.1.1\kuangjia_new\testcases\test_my_push.py", line 76, in test001_my_push
    self.assertEqual(expected['code'], result['code'])
  File "D:\PyCharm Community Edition 2020.1.1\plugins\python-ce\helpers\pycharm\teamcity\diff_tools.py", line 38, in _patched_equals
    raise error
teamcity.diff_tools.EqualsAssertionError:  :: 1 != 2
2020-08-27 22:50:02,669 - [test_my_push.py-->line:82] - ERROR:用例上架中执行不通过
2020-08-27 22:50:02,669 - [test_my_push.py-->line:84] - ERROR: :: 1 != 2
Traceback (most recent call last):
  File "D:\PyCharm Community Edition 2020.1.1\plugins\python-ce\helpers\pycharm\teamcity\diff_tools.py", line 32, in _patched_equals
    old(self, first, second, msg)
  File "C:\Users\22235\AppData\Local\Programs\Python\Python37\lib\unittest\case.py", line 852, in assertEqual
    assertion_func(first, second, msg=msg)
  File "C:\Users\22235\AppData\Local\Programs\Python\Python37\lib\unittest\case.py", line 845, in _baseAssertEqual
    raise self.failureException(msg)
AssertionError: 1 != 2

During handling of the above exception, another exception occurred:

Traceback (most recent call last):
  File "D:\PyCharm Community Edition 2020.1.1\kuangjia_new\testcases\test_my_push.py", line 76, in test001_my_push
    self.assertEqual(expected['code'], result['code'])
  File "D:\PyCharm Community Edition 2020.1.1\plugins\python-ce\helpers\pycharm\teamcity\diff_tools.py", line 38, in _patched_equals
    raise error
teamcity.diff_tools.EqualsAssertionError:  :: 1 != 2
2020-08-27 22:50:02,772 - [test_my_push.py-->line:82] - ERROR:用例店铺分类为空执行不通过
2020-08-27 22:50:02,772 - [test_my_push.py-->line:84] - ERROR: :: 0 != 2
Traceback (most recent call last):
  File "D:\PyCharm Community Edition 2020.1.1\plugins\python-ce\helpers\pycharm\teamcity\diff_tools.py", line 32, in _patched_equals
    old(self, first, second, msg)
  File "C:\Users\22235\AppData\Local\Programs\Python\Python37\lib\unittest\case.py", line 852, in assertEqual
    assertion_func(first, second, msg=msg)
  File "C:\Users\22235\AppData\Local\Programs\Python\Python37\lib\unittest\case.py", line 845, in _baseAssertEqual
    raise self.failureException(msg)
AssertionError: 0 != 2

During handling of the above exception, another exception occurred:

Traceback (most recent call last):
  File "D:\PyCharm Community Edition 2020.1.1\kuangjia_new\testcases\test_my_push.py", line 76, in test001_my_push
    self.assertEqual(expected['code'], result['code'])
  File "D:\PyCharm Community Edition 2020.1.1\plugins\python-ce\helpers\pycharm\teamcity\diff_tools.py", line 38, in _patched_equals
    raise error
teamcity.diff_tools.EqualsAssertionError:  :: 0 != 2
2020-08-27 22:52:46,692 - [handlelog.py-->line:39] - INFO:调试一下下
2020-08-27 22:53:38,049 - [handlelog.py-->line:39] - INFO:调试一下下
2020-08-27 22:54:05,484 - [handlelog.py-->line:39] - INFO:调试一下下
2020-08-27 22:54:14,015 - [handlelog.py-->line:39] - INFO:调试一下下
2020-09-15 23:08:52,911 - [handlelog.py-->line:39] - INFO:调试一下下
